Workbook

Sheet Base Mercado
A1: ID Mercado | B1: Grupo Mercado | C1: Nome | D1: Endereço Completo | E1: Link Maps | F1: Latitude | G1: Longitude | H1: País | I1: Estado | J1: Cidade | K1: Bairro | L1: Rua | M1: Número
A2: 1 | B2: União | C2: União - Jardim Bonança | D2: Avenida Embauba, Nº 42 - Jardim Bonança, Bragança Paulista - SP, 12929-899 | E2: https://www.google.com/maps/place/Uni%C3%A3o+Supermercados+Bragan%C3%A7a+15/@-22.9127974,-46.5620651,955m/data=!3m1!1e3!4m10!1m2!2m1!1sAvenida+Embauba,+N%C2%BA+42+-+Jardim+Bonan%C3%A7a,+Bragan%C3%A7a+Paulista+-+SP,+12929-899!3m6!1s0x94cecb732203c803:0x430a338895b87114!8m2!3d-22.9128062!4d-46.5593992!15sCk1BdmVuaWRhIEVtYmF1YmEsIE7CuiA0MiAtIEphcmRpbSBCb25hbsOnYSwgQnJhZ2Fuw6dhIFBhdWxpc3RhIC0gU1AsIDEyOTI5LTg5OVpIIkZhdmVuaWRhIGVtYmF1YmEgbsK6IDQyIGphcmRpbSBib25hbsOnYSBicmFnYW7Dp2EgcGF1bGlzdGEgc3AgMTI5MjkgODk5kgELc3VwZXJtYXJrZXSaAURDaTlEUVVsUlFVTnZaRU5vZEhsalJqbHZUMnBHVG1KNldsTldSWGgzVWtSc1ZVNHhXakpOYmtwVFQwaG5NbU14UlJBQuABAPoBBAgAEEM!16s%2Fg%2F11jgdhsn4h?entry=ttu&g_ep=EgoyMDI2MDQyOS4wIKXMDSoASAFQAw%3D%3D | F2: -22.912806 | G2: -46.559399 | H2: Brasil | I2: SP | J2: Bragança Paulista | K2: Jardim Bonança | L2: Avenida Embauba | M2: 42
A3: =A2+1 -> 2 | B3: Mendonça | C3: Mendonça - Parque dos Estados | D3: Av. Dep. Virgílio de Carvalho Pinto, 601 - Cidade Planejada I, Bragança Paulista - SP, 12922-160 | E3: https://www.google.com/maps/place/S+M+Supermercados+Mendon%C3%A7a/@-22.9162371,-46.5542733,131m/data=!3m1!1e3!4m15!1m8!3m7!1s0x94ceca5359d07237:0xa67ce8b83d5c5924!2sAv.+Dep.+Virg%C3%ADlio+de+Carvalho+Pinto,+601+-+Cidade+Planejada+I,+Bragan%C3%A7a+Paulista+-+SP,+12922-160!3b1!8m2!3d-22.9159587!4d-46.5541454!16s%2Fg%2F11dzw7hddv!3m5!1s0x94ceca535c993fd3:0xae6d8aca79a533d9!8m2!3d-22.916002!4d-46.554093!16s%2Fg%2F1tn02cb2?entry=ttu&g_ep=EgoyMDI2MDQyOS4wIKXMDSoASAFQAw%3D%3D | F3: -22.916002 | G3: -46.554093 | H3: Brasil | I3: SP | J3: Bragança Paulista | K3: Cidade Planejada I | L3: Av. Dep. Virgílio de Carvalho Pinto | M3: 601
A4: =A3+1 -> 3 | B4: União | C4: União - Centro | D4: Av. José Gomes da Rocha Leal, 1151 - Centro, Bragança Paulista - SP, 12900-300 | E4: https://www.google.com/maps/place/Uni%C3%A3o+Supermercados+Loja+12/@-22.956931,-46.5454349,188m/data=!3m2!1e3!5s0x94cec99074c2886f:0xddfd7615075b6ee6!4m15!1m8!3m7!1s0x94cec9907432ffc9:0xe6ad19cdc779ca46!2sAv.+Jos%C3%A9+Gomes+da+Rocha+Leal,+1151+-+Centro,+Bragan%C3%A7a+Paulista+-+SP,+12900-301!3b1!8m2!3d-22.9569399!4d-46.5449966!16s%2Fg%2F11kqfwjqqh!3m5!1s0x94cec98e4922e61b:0x6d15aa71015795f6!8m2!3d-22.9566842!4d-46.5450148!16s%2Fg%2F11c1r6d0n6?entry=ttu&g_ep=EgoyMDI2MDQyOS4wIKXMDSoASAFQAw%3D%3D | F4: -22.956684 | G4: -46.545015 | H4: Brasil | I4: SP | J4: Bragança Paulista | K4: Centro | L4: Av. José Gomes da Rocha Leal | M4: 1151
A5: =A4+1 -> 4 | B5: Mendonça | C5: Mendonça - Centro | D5: Av. dos Imigrantes, 2120 - Centro, Bragança Paulista - SP, 12900-500 | E5: https://www.google.com/maps/place/SM+Supermercados+Mendon%C3%A7a/@-22.9549011,-46.5467033,60m/data=!3m1!1e3!4m6!3m5!1s0x94cec9b652bfad4b:0xe28494aa969062bf!8m2!3d-22.955059!4d-46.5464874!16s%2Fg%2F11tsjz5j87?entry=ttu&g_ep=EgoyMDI2MDQyOS4wIKXMDSoASAFQAw%3D%3D | F5: -22.955059 | G5: -46.546487 | H5: Brasil | I5: SP | J5: Bragança Paulista | K5: Centro | L5: Av. dos Imigrantes | M5: 2120
A6: =A5+1 -> 5 | B6: Comercial Esperança | C6: Comercial Esperança - Penha | D6: Alameda Quinze de Dezembro, 100 - Jardim Dr. Julio de Mesquita Filho, Bragança Paulista - SP, 12910-690 | E6: https://www.google.com/maps/place/Comercial+Esperan%C3%A7a/@-22.949963,-46.5303561,544m/data=!3m1!1e3!4m10!1m2!2m1!1sComercial+Esperan%C3%A7a!3m6!1s0x94cec9f707c9aeb9:0x33b072a118dc6ac1!8m2!3d-22.9489138!4d-46.5282191!15sChRDb21lcmNpYWwgRXNwZXJhbsOnYSIDiAEBWhYiFGNvbWVyY2lhbCBlc3BlcmFuw6dhkgELc3VwZXJtYXJrZXTgAQA!16s%2Fg%2F11gdgxbxh9?entry=ttu&g_ep=EgoyMDI2MDQyOS4wIKXMDSoASAFQAw%3D%3D | F6: -22.948914 | G6: -46.528219 | H6: Brasil | I6: SP | J6: Bragança Paulista | K6: Jardim Dr. Julio de Mesquita Filho | L6: Alameda Quinze de Dezembro | M6: 100
A7: =A6+1 -> 6 | B7: Spani Atacadista | C7: Spani Atacadista - Lago | D7: Av. Dom Pedro I, 1025 - Jardim Nova Braganca, Bragança Paulista - SP, 12914-481 | E7: https://www.google.com/maps/place/Spani+Atacadista+Bragan%C3%A7a+Paulista/@-22.9748667,-46.5334056,464m/data=!3m1!1e3!4m14!1m7!3m6!1s0x94cec9c9a16667c5:0x4a8281cc82bddfb6!2sAv.+Dom+Pedro+I,+1025+-+Jardim+Nova+Braganca,+Bragan%C3%A7a+Paulista+-+SP,+12914-481!3b1!8m2!3d-22.9739196!4d-46.5332996!3m5!1s0x94cec9cbdd37a931:0x614da09215bc8783!8m2!3d-22.974678!4d-46.5300865!16s%2Fg%2F11fy5j9_jd?entry=ttu&g_ep=EgoyMDI2MDQyOS4wIKXMDSoASAFQAw%3D%3D | F7: -22.974678 | G7: -46.530087 | H7: Brasil | I7: SP | J7: Bragança Paulista | K7: Jardim Nova Braganca | L7: Av. Dom Pedro I | M7: 1025
A8: =A7+1 -> 7 | B8: Spani Atacadista | C8: Spani Atacadista - Lavapés | D8: R. Monteiro Lobato, 120 - Lavapés, Bragança Paulista - SP, 12903-110 | E8: https://www.google.com/maps/place/Spani+Atacadista+Bragan%C3%A7a+Paulista/@-22.9471257,-46.5451426,60m/data=!3m1!1e3!4m6!3m5!1s0x94cec988769f65df:0x740994c95fa8fbb1!8m2!3d-22.9470567!4d-46.5448719!16s%2Fg%2F11cmfggvbx?entry=ttu&g_ep=EgoyMDI2MDQyOS4wIKXMDSoASAFQAw%3D%3D | F8: -22.947057 | G8: -46.544872 | H8: Brasil | I8: SP | J8: Bragança Paulista | K8: Lavapés | L8: R. Monteiro Lobato | M8: 120

Sheet Pontos de Partida
A1: ID Endereço | B1: Endereço Completo | C1: Região | D1: Link Maps | E1: Latitude | F1: Longitude | G1: País | H1: Estado | I1: Cidade | J1: Bairro | K1: Rua | L1: Número
A2: 1 | B2: Av. Dr. Manoel José Vilaça - Jardim America, Bragança Paulista - SP | C2: Centro | D2: https://www.google.com/maps/place/Av.+Dr.+Manoel+Jos%C3%A9+Vila%C3%A7a+-+Jardim+America,+Bragan%C3%A7a+Paulista+-+SP/@-22.9572979,-46.5490002,239m/data=!3m2!1e3!4b1!4m9!1m2!2m1!1sRua+das+Tipuanas,+Jardim+Am%C3%A9rica,+Bragan%C3%A7a+Paulista+-+SP!3m5!1s0x94cec99b2135ac67:0xc7820a80c637de20!8m2!3d-22.9572991!4d-46.5477825!16s%2Fg%2F11g60rq39q?entry=ttu&g_ep=EgoyMDI2MDQyOS4wIKXMDSoASAFQAw%3D%3D | E2: -22.957299 | F2: -46.547782 | G2: Brasil | H2: SP | I2: Bragança Paulista | J2: Jardim America | K2: Av. Dr. Manoel José Vilaça
A3: =A2+1 -> 2 | B3: R. Adele Pagetti - Cidade Planejada I, Bragança Paulista - SP, 12922-060 | C3: Norte | D3: https://www.google.com/maps/place/Personalizados+Marquezini/@-22.9174026,-46.5626729,955m/data=!3m2!1e3!4b1!4m15!1m8!3m7!1s0x94ceca533dee78e7:0x30241aa53d2c8dd1!2sAv.+Dep.+Virg%C3%ADlio+de+Carvalho+Pinto+-+Cidade+Nova,+Bragan%C3%A7a+Paulista+-+SP,+12922-754!3b1!8m2!3d-22.9172554!4d-46.5542177!16s%2Fg%2F1ymx8qcsg!3m5!1s0x94cecb00a61ae861:0xd32c83b10b80bbe4!8m2!3d-22.9174076!4d-46.557802!16s%2Fg%2F11x1p3psbq?entry=ttu&g_ep=EgoyMDI2MDQyOS4wIKXMDSoASAFQAw%3D%3D | E3: -22.917408 | F3: -46.557802 | G3: Brasil | H3: SP | I3: Bragança Paulista | J3: Cidade Planejada I | K3: R. Adele Pagetti
A4: =A3+1 -> 3 | B4: R. Ruth Franco Rocha - São Lourenço, Bragança Paulista - SP, 12908-730 | C4: Noroeste | D4: https://www.google.com/maps/place/R.+Ruth+Franco+Rocha,+349+-+S%C3%A3o+Louren%C3%A7o,+Bragan%C3%A7a+Paulista+-+SP,+12908-730/@-22.9368356,-46.544606,955m/data=!3m2!1e3!4b1!4m15!1m8!3m7!1s0x94ceca25b0d664ff:0x52f64613e96e150e!2sAv.+dos+Imigrantes,+Bragan%C3%A7a+Paulista+-+SP!3b1!8m2!3d-22.941054!4d-46.5407478!16s%2Fg%2F1ymxglp6q!3m5!1s0x94ceca24ebedb429:0xf392671e336a2891!8m2!3d-22.9368385!4d-46.5417718!16s%2Fg%2F11vlw1qlsz?entry=ttu&g_ep=EgoyMDI2MDQyOS4wIKXMDSoASAFQAw%3D%3D | E4: -22.936839 | F4: -46.541772 | G4: Brasil | H4: SP | I4: Bragança Paulista | J4: São Lourenço | K4: R. Ruth Franco Rocha
A5: =A4+1 -> 4 | B5: R. da Tecnologia - Res. Hipica Jaguari, Bragança Paulista - SP, 12926-677 | C5: Norte | D5: https://www.google.com/maps/place/R.+da+Tecnologia,+536+-+Res.+Hipica+Jaguari,+Bragan%C3%A7a+Paulista+-+SP,+12926-677/@-22.9239452,-46.5463773,955m/data=!3m2!1e3!4b1!4m6!3m5!1s0x94ceca464a4af643:0xe8980db9bb81c804!8m2!3d-22.9239502!4d-46.5438024!16s%2Fg%2F11fpnny18_?entry=ttu&g_ep=EgoyMDI2MDQyOS4wIKXMDSoASAFQAw%3D%3D | E5: -22.92395 | F5: -46.543802 | G5: Brasil | H5: SP | I5: Bragança Paulista | J5: Res. Hipica Jaguari | K5: R. da Tecnologia
A6: =A5+1 -> 5 | B6: R. Expedicionário José Franco de Macedo - Penha, Bragança Paulista - SP, 12929-460 | C6: Leste | D6: https://www.google.com/maps/place/R.+Expedicion%C3%A1rio+Jos%C3%A9+Franco+de+Macedo,+871-809+-+Penha,+Bragan%C3%A7a+Paulista+-+SP,+12929-460/@-22.9387218,-46.5399746,5975m/data=!3m1!1e3!4m15!1m8!3m7!1s0x94cec9870b781e47:0x21c2ad1992f2085c!2sR.+Carvalho+Mota,+192+-+Vila+Mota,+Bragan%C3%A7a+Paulista+-+SP,+12903-170!3b1!8m2!3d-22.9482546!4d-46.5478233!16s%2Fg%2F11g8bbvb76!3m5!1s0x94cec9ffce7c8f41:0xfd759d4697d01a7f!8m2!3d-22.9385127!4d-46.5170027!16s%2Fg%2F11g656vfny?entry=ttu&g_ep=EgoyMDI2MDQyOS4wIKXMDSoASAFQAw%3D%3D | E6: -22.938513 | F6: -46.517003 | G6: Brasil | H6: SP | I6: Bragança Paulista | J6: Penha | K6: R. Expedicionário José Franco de Macedo
A7: =A6+1 -> 6 | B7: R. Dijon - Res. Euroville, Bragança Paulista - SP | C7: Sul | D7: https://www.google.com/maps/place/R.+Dijon,+109-1+-+Res.+Euroville,+Bragan%C3%A7a+Paulista+-+SP/@-22.9807599,-46.5482368,477m/data=!3m2!1e3!4b1!4m6!3m5!1s0x94cec9add2af3391:0x33258ce5dd3ba25b!8m2!3d-22.9807616!4d-46.5473395!16s%2Fg%2F11c65nkwfq?entry=ttu&g_ep=EgoyMDI2MDQyOS4wIKXMDSoASAFQAw%3D%3D | E7: -22.980762 | F7: -46.547339 | G7: Brasil | H7: SP | I7: Bragança Paulista | J7: Res. Euroville | K7: R. Dijon
A8: =A7+1 -> 7 | B8: R. Sangiovese - Jardins, Bragança Paulista - SP, 12903-794 | C8: Oeste | D8: https://www.google.com/maps/place/R.+Sangiovese,+159+-+Jardins,+Bragan%C3%A7a+Paulista+-+SP,+12903-794/@-22.9340417,-46.5712307,955m/data=!3m2!1e3!4b1!4m6!3m5!1s0x94cecbb8b5b67537:0x74cc4283a1d945bd!8m2!3d-22.934046!4d-46.569018!16s%2Fg%2F11x2m580m_?entry=ttu&g_ep=EgoyMDI2MDQyOS4wIKXMDSoASAFQAw%3D%3D | E8: -22.934046 | F8: -46.569018 | G8: Brasil | H8: SP | I8: Bragança Paulista | J8: Jardins | K8: R. Sangiovese
A9: =A8+1 -> 8 | B9: R. Cel. Luís Leme - Jardim Santa Rita de Cassia, Bragança Paulista - SP, 12914-010 | C9: Centro | D9: https://www.google.com/maps/place/R.+Cel.+Lu%C3%ADs+Leme,+118-170+-+Jardim+Santa+Rita+de+Cassia,+Bragan%C3%A7a+Paulista+-+SP,+12914-010/@-22.9558097,-46.539459,477m/data=!3m2!1e3!4b1!4m6!3m5!1s0x94cec993b2f63949:0x5495e4059e533f70!8m2!3d-22.9558116!4d-46.5384518!16s%2Fg%2F11c622qlwv?entry=ttu&g_ep=EgoyMDI2MDQyOS4wIKXMDSoASAFQAw%3D%3D | E9: -22.955812 | F9: -46.538452 | G9: Brasil | H9: SP | I9: Bragança Paulista | J9: Jardim Santa Rita de Cassia | K9: R. Cel. Luís Leme

Sheet Produtos & Marcas
A1: ID Produto | B1: Chave de Escolha | C1: Categoria Produto | D1: Unidade de Medida | E1: Peso | F1: Marca ou Tipo
A2: 1 | B2: =CONCATENATE(C2," | ",F2," | ",E2," | ",D2) -> Açúcar | Caravelas | 1 | Kg | C2: Açúcar | D2: Kg | E2: 1 | F2: Caravelas
A3: 2 | B3: =CONCATENATE(C3," | ",F3," | ",E3," | ",D3) -> Açúcar | União | 1 | Kg | C3: Açúcar | D3: Kg | E3: 1 | F3: União
A4: 3 | B4: =CONCATENATE(C4," | ",F4," | ",E4," | ",D4) -> Açúcar | Guarani | 1 | Kg | C4: Açúcar | D4: Kg | E4: 1 | F4: Guarani
A5: 4 | B5: =CONCATENATE(C5," | ",F5," | ",E5," | ",D5) -> Arroz | Namorado | 1 | Kg | C5: Arroz | D5: Kg | E5: 1 | F5: Namorado
A6: 5 | B6: =CONCATENATE(C6," | ",F6," | ",E6," | ",D6) -> Arroz | Tio João | 1 | Kg | C6: Arroz | D6: Kg | E6: 1 | F6: Tio João
A7: 6 | B7: =CONCATENATE(C7," | ",F7," | ",E7," | ",D7) -> Arroz | Prato Fino | 1 | Kg | C7: Arroz | D7: Kg | E7: 1 | F7: Prato Fino
A8: 7 | B8: =CONCATENATE(C8," | ",F8," | ",E8," | ",D8) -> Banana | Banana Nanica | 1 | Kg | C8: Banana | D8: Kg | E8: 1 | F8: Banana Nanica
A9: 8 | B9: =CONCATENATE(C9," | ",F9," | ",E9," | ",D9) -> Banana | Banana Prata | 1 | Kg | C9: Banana | D9: Kg | E9: 1 | F9: Banana Prata
A10: 9 | B10: =CONCATENATE(C10," | ",F10," | ",E10," | ",D10) -> Banana | Banana Maçã | 1 | Kg | C10: Banana | D10: Kg | E10: 1 | F10: Banana Maçã
A11: 10 | B11: =CONCATENATE(C11," | ",F11," | ",E11," | ",D11) -> Batata | Batata Inglesa | 1 | Kg | C11: Batata | D11: Kg | E11: 1 | F11: Batata Inglesa
A12: 11 | B12: =CONCATENATE(C12," | ",F12," | ",E12," | ",D12) -> Batata | Batata Asterix selecionada | 1 | Kg | C12: Batata | D12: Kg | E12: 1 | F12: Batata Asterix selecionada
A13: 12 | B13: =CONCATENATE(C13," | ",F13," | ",E13," | ",D13) -> Batata | Batata doce | 1 | Kg | C13: Batata | D13: Kg | E13: 1 | F13: Batata doce
... A40: 39 | B40: =CONCATENATE(C40," | ",F40," | ",E40," | ",D40) -> Tomate | Tomate cereja | 0,25 | Kg | C40: Tomate | D40: Kg | E40: 0.25 | F40: Tomate cereja

Sheet Produtos & Mercados
A1: ID Produto | B1: Chave de Escolha | C1: Categoria Produto | D1: Unidade de Medida | E1: Peso | F1: Preço por Unidade de Medida | G1: Marca ou Tipo | H1: Mercado | I1: ID Mercado | J1: Preço | K1: Preço com Desconto | L1: Preço Final | M1: Data Coleta de preço
A2: 1 | B2: =_xlfn.XLOOKUP(A2,'Produtos & Marcas'!A:A,'Produtos & Marcas'!B:B) -> Açúcar | Caravelas | 1 | Kg | C2: =_xlfn.XLOOKUP(B2,'Produtos & Marcas'!B:B,'Produtos & Marcas'!C:C) -> Açúcar | D2: =_xlfn.XLOOKUP(B2,'Produtos & Marcas'!B:B,'Produtos & Marcas'!D:D) -> Kg | E2: =_xlfn.XLOOKUP(B2,'Produtos & Marcas'!B:B,'Produtos & Marcas'!E:E) -> 1 | F2: =J2/E2 -> 3.99 | G2: =_xlfn.XLOOKUP(B2,'Produtos & Marcas'!B:B,'Produtos & Marcas'!F:F) -> Caravelas | H2: União - Jardim Bonança | I2: =_xlfn.XLOOKUP(H2,'Base Mercado'!C:C,'Base Mercado'!A:A) -> 1 | J2: 3.99 | K2: 3.89 | L2: =IF(AND(K2<>"",K2<J2),K2,J2) -> 3.89
A3: 1 | B3: =_xlfn.XLOOKUP(A3,'Produtos & Marcas'!A:A,'Produtos & Marcas'!B:B) -> Açúcar | Caravelas | 1 | Kg | C3: =_xlfn.XLOOKUP(B3,'Produtos & Marcas'!B:B,'Produtos & Marcas'!C:C) -> Açúcar | D3: =_xlfn.XLOOKUP(B3,'Produtos & Marcas'!B:B,'Produtos & Marcas'!D:D) -> Kg | E3: =_xlfn.XLOOKUP(B3,'Produtos & Marcas'!B:B,'Produtos & Marcas'!E:E) -> 1 | F3: =J3/E3 -> 2.99 | G3: =_xlfn.XLOOKUP(B3,'Produtos & Marcas'!B:B,'Produtos & Marcas'!F:F) -> Caravelas | H3: Mendonça - Parque dos Estados | I3: =_xlfn.XLOOKUP(H3,'Base Mercado'!C:C,'Base Mercado'!A:A) -> 2 | J3: 2.99 | L3: =IF(AND(K3<>"",K3<J3),K3,J3) -> 2.99
A4: 1 | B4: =_xlfn.XLOOKUP(A4,'Produtos & Marcas'!A:A,'Produtos & Marcas'!B:B) -> Açúcar | Caravelas | 1 | Kg | C4: =_xlfn.XLOOKUP(B4,'Produtos & Marcas'!B:B,'Produtos & Marcas'!C:C) -> Açúcar | D4: =_xlfn.XLOOKUP(B4,'Produtos & Marcas'!B:B,'Produtos & Marcas'!D:D) -> Kg | E4: =_xlfn.XLOOKUP(B4,'Produtos & Marcas'!B:B,'Produtos & Marcas'!E:E) -> 1 | F4: =J4/E4 -> 3.99 | G4: =_xlfn.XLOOKUP(B4,'Produtos & Marcas'!B:B,'Produtos & Marcas'!F:F) -> Caravelas | H4: União - Centro | I4: =_xlfn.XLOOKUP(H4,'Base Mercado'!C:C,'Base Mercado'!A:A) -> 3 | J4: 3.99 | K4: 3.84 | L4: =IF(AND(K4<>"",K4<J4),K4,J4) -> 3.84
A5: 1 | B5: =_xlfn.XLOOKUP(A5,'Produtos & Marcas'!A:A,'Produtos & Marcas'!B:B) -> Açúcar | Caravelas | 1 | Kg | C5: =_xlfn.XLOOKUP(B5,'Produtos & Marcas'!B:B,'Produtos & Marcas'!C:C) -> Açúcar | D5: =_xlfn.XLOOKUP(B5,'Produtos & Marcas'!B:B,'Produtos & Marcas'!D:D) -> Kg | E5: =_xlfn.XLOOKUP(B5,'Produtos & Marcas'!B:B,'Produtos & Marcas'!E:E) -> 1 | F5: =J5/E5 -> 2.99 | G5: =_xlfn.XLOOKUP(B5,'Produtos & Marcas'!B:B,'Produtos & Marcas'!F:F) -> Caravelas | H5: Mendonça - Centro | I5: =_xlfn.XLOOKUP(H5,'Base Mercado'!C:C,'Base Mercado'!A:A) -> 4 | J5: 2.99 | L5: =IF(AND(K5<>"",K5<J5),K5,J5) -> 2.99
A6: 1 | B6: =_xlfn.XLOOKUP(A6,'Produtos & Marcas'!A:A,'Produtos & Marcas'!B:B) -> Açúcar | Caravelas | 1 | Kg | C6: =_xlfn.XLOOKUP(B6,'Produtos & Marcas'!B:B,'Produtos & Marcas'!C:C) -> Açúcar | D6: =_xlfn.XLOOKUP(B6,'Produtos & Marcas'!B:B,'Produtos & Marcas'!D:D) -> Kg | E6: =_xlfn.XLOOKUP(B6,'Produtos & Marcas'!B:B,'Produtos & Marcas'!E:E) -> 1 | F6: =J6/E6 -> 4.99 | G6: =_xlfn.XLOOKUP(B6,'Produtos & Marcas'!B:B,'Produtos & Marcas'!F:F) -> Caravelas | H6: Comercial Esperança - Penha | I6: =_xlfn.XLOOKUP(H6,'Base Mercado'!C:C,'Base Mercado'!A:A) -> 5 | J6: 4.99 | L6: =IF(AND(K6<>"",K6<J6),K6,J6) -> 4.99
A7: 1 | B7: =_xlfn.XLOOKUP(A7,'Produtos & Marcas'!A:A,'Produtos & Marcas'!B:B) -> Açúcar | Caravelas | 1 | Kg | C7: =_xlfn.XLOOKUP(B7,'Produtos & Marcas'!B:B,'Produtos & Marcas'!C:C) -> Açúcar | D7: =_xlfn.XLOOKUP(B7,'Produtos & Marcas'!B:B,'Produtos & Marcas'!D:D) -> Kg | E7: =_xlfn.XLOOKUP(B7,'Produtos & Marcas'!B:B,'Produtos & Marcas'!E:E) -> 1 | F7: =J7/E7 -> 5.99 | G7: =_xlfn.XLOOKUP(B7,'Produtos & Marcas'!B:B,'Produtos & Marcas'!F:F) -> Caravelas | H7: Spani Atacadista - Lago | I7: =_xlfn.XLOOKUP(H7,'Base Mercado'!C:C,'Base Mercado'!A:A) -> 6 | J7: 5.99 | L7: =IF(AND(K7<>"",K7<J7),K7,J7) -> 5.99
A8: 1 | B8: =_xlfn.XLOOKUP(A8,'Produtos & Marcas'!A:A,'Produtos & Marcas'!B:B) -> Açúcar | Caravelas | 1 | Kg | C8: =_xlfn.XLOOKUP(B8,'Produtos & Marcas'!B:B,'Produtos & Marcas'!C:C) -> Açúcar | D8: =_xlfn.XLOOKUP(B8,'Produtos & Marcas'!B:B,'Produtos & Marcas'!D:D) -> Kg | E8: =_xlfn.XLOOKUP(B8,'Produtos & Marcas'!B:B,'Produtos & Marcas'!E:E) -> 1 | F8: =J8/E8 -> 2.99 | G8: =_xlfn.XLOOKUP(B8,'Produtos & Marcas'!B:B,'Produtos & Marcas'!F:F) -> Caravelas | H8: Spani Atacadista - Lavapés | I8: =_xlfn.XLOOKUP(H8,'Base Mercado'!C:C,'Base Mercado'!A:A) -> 7 | J8: 2.99 | K8: 2.91 | L8: =IF(AND(K8<>"",K8<J8),K8,J8) -> 2.91
A9: 3 | B9: =_xlfn.XLOOKUP(A9,'Produtos & Marcas'!A:A,'Produtos & Marcas'!B:B) -> Açúcar | Guarani | 1 | Kg | C9: =_xlfn.XLOOKUP(B9,'Produtos & Marcas'!B:B,'Produtos & Marcas'!C:C) -> Açúcar | D9: =_xlfn.XLOOKUP(B9,'Produtos & Marcas'!B:B,'Produtos & Marcas'!D:D) -> Kg | E9: =_xlfn.XLOOKUP(B9,'Produtos & Marcas'!B:B,'Produtos & Marcas'!E:E) -> 1 | F9: =J9/E9 -> 3.79 | G9: =_xlfn.XLOOKUP(B9,'Produtos & Marcas'!B:B,'Produtos & Marcas'!F:F) -> Guarani | H9: União - Jardim Bonança | I9: =_xlfn.XLOOKUP(H9,'Base Mercado'!C:C,'Base Mercado'!A:A) -> 1 | J9: 3.79 | L9: =IF(AND(K9<>"",K9<J9),K9,J9) -> 3.79
A10: 3 | B10: =_xlfn.XLOOKUP(A10,'Produtos & Marcas'!A:A,'Produtos & Marcas'!B:B) -> Açúcar | Guarani | 1 | Kg | C10: =_xlfn.XLOOKUP(B10,'Produtos & Marcas'!B:B,'Produtos & Marcas'!C:C) -> Açúcar | D10: =_xlfn.XLOOKUP(B10,'Produtos & Marcas'!B:B,'Produtos & Marcas'!D:D) -> Kg | E10: =_xlfn.XLOOKUP(B10,'Produtos & Marcas'!B:B,'Produtos & Marcas'!E:E) -> 1 | F10: =J10/E10 -> 5.79 | G10: =_xlfn.XLOOKUP(B10,'Produtos & Marcas'!B:B,'Produtos & Marcas'!F:F) -> Guarani | H10: Mendonça - Parque dos Estados | I10: =_xlfn.XLOOKUP(H10,'Base Mercado'!C:C,'Base Mercado'!A:A) -> 2 | J10: 5.79 | L10: =IF(AND(K10<>"",K10<J10),K10,J10) -> 5.79
A11: 3 | B11: =_xlfn.XLOOKUP(A11,'Produtos & Marcas'!A:A,'Produtos & Marcas'!B:B) -> Açúcar | Guarani | 1 | Kg | C11: =_xlfn.XLOOKUP(B11,'Produtos & Marcas'!B:B,'Produtos & Marcas'!C:C) -> Açúcar | D11: =_xlfn.XLOOKUP(B11,'Produtos & Marcas'!B:B,'Produtos & Marcas'!D:D) -> Kg | E11: =_xlfn.XLOOKUP(B11,'Produtos & Marcas'!B:B,'Produtos & Marcas'!E:E) -> 1 | F11: =J11/E11 -> 2.79 | G11: =_xlfn.XLOOKUP(B11,'Produtos & Marcas'!B:B,'Produtos & Marcas'!F:F) -> Guarani | H11: União - Centro | I11: =_xlfn.XLOOKUP(H11,'Base Mercado'!C:C,'Base Mercado'!A:A) -> 3 | J11: 2.79 | K11: 2.67 | L11: =IF(AND(K11<>"",K11<J11),K11,J11) -> 2.67
A12: 3 | B12: =_xlfn.XLOOKUP(A12,'Produtos & Marcas'!A:A,'Produtos & Marcas'!B:B) -> Açúcar | Guarani | 1 | Kg | C12: =_xlfn.XLOOKUP(B12,'Produtos & Marcas'!B:B,'Produtos & Marcas'!C:C) -> Açúcar | D12: =_xlfn.XLOOKUP(B12,'Produtos & Marcas'!B:B,'Produtos & Marcas'!D:D) -> Kg | E12: =_xlfn.XLOOKUP(B12,'Produtos & Marcas'!B:B,'Produtos & Marcas'!E:E) -> 1 | F12: =J12/E12 -> 2.79 | G12: =_xlfn.XLOOKUP(B12,'Produtos & Marcas'!B:B,'Produtos & Marcas'!F:F) -> Guarani | H12: Mendonça - Centro | I12: =_xlfn.XLOOKUP(H12,'Base Mercado'!C:C,'Base Mercado'!A:A) -> 4 | J12: 2.79 | L12: =IF(AND(K12<>"",K12<J12),K12,J12) -> 2.79
A13: 3 | B13: =_xlfn.XLOOKUP(A13,'Produtos & Marcas'!A:A,'Produtos & Marcas'!B:B) -> Açúcar | Guarani | 1 | Kg | C13: =_xlfn.XLOOKUP(B13,'Produtos & Marcas'!B:B,'Produtos & Marcas'!C:C) -> Açúcar | D13: =_xlfn.XLOOKUP(B13,'Produtos & Marcas'!B:B,'Produtos & Marcas'!D:D) -> Kg | E13: =_xlfn.XLOOKUP(B13,'Produtos & Marcas'!B:B,'Produtos & Marcas'!E:E) -> 1 | F13: =J13/E13 -> 2.79 | G13: =_xlfn.XLOOKUP(B13,'Produtos & Marcas'!B:B,'Produtos & Marcas'!F:F) -> Guarani | H13: Comercial Esperança - Penha | I13: =_xlfn.XLOOKUP(H13,'Base Mercado'!C:C,'Base Mercado'!A:A) -> 5 | J13: 2.79 | K13: 2.59 | L13: =IF(AND(K13<>"",K13<J13),K13,J13) -> 2.59
A14: 3 | B14: =_xlfn.XLOOKUP(A14,'Produtos & Marcas'!A:A,'Produtos & Marcas'!B:B) -> Açúcar | Guarani | 1 | Kg | C14: =_xlfn.XLOOKUP(B14,'Produtos & Marcas'!B:B,'Produtos & Marcas'!C:C) -> Açúcar | D14: =_xlfn.XLOOKUP(B14,'Produtos & Marcas'!B:B,'Produtos & Marcas'!D:D) -> Kg | E14: =_xlfn.XLOOKUP(B14,'Produtos & Marcas'!B:B,'Produtos & Marcas'!E:E) -> 1 | F14: =J14/E14 -> 4.79 | G14: =_xlfn.XLOOKUP(B14,'Produtos & Marcas'!B:B,'Produtos & Marcas'!F:F) -> Guarani | H14: Spani Atacadista - Lago | I14: =_xlfn.XLOOKUP(H14,'Base Mercado'!C:C,'Base Mercado'!A:A) -> 6 | J14: 4.79 | K14: 4.54 | L14: =IF(AND(K14<>"",K14<J14),K14,J14) -> 4.54
A15: 3 | B15: =_xlfn.XLOOKUP(A15,'Produtos & Marcas'!A:A,'Produtos & Marcas'!B:B) -> Açúcar | Guarani | 1 | Kg | C15: =_xlfn.XLOOKUP(B15,'Produtos & Marcas'!B:B,'Produtos & Marcas'!C:C) -> Açúcar | D15: =_xlfn.XLOOKUP(B15,'Produtos & Marcas'!B:B,'Produtos & Marcas'!D:D) -> Kg | E15: =_xlfn.XLOOKUP(B15,'Produtos & Marcas'!B:B,'Produtos & Marcas'!E:E) -> 1 | F15: =J15/E15 -> 3.79 | G15: =_xlfn.XLOOKUP(B15,'Produtos & Marcas'!B:B,'Produtos & Marcas'!F:F) -> Guarani | H15: Spani Atacadista - Lavapés | I15: =_xlfn.XLOOKUP(H15,'Base Mercado'!C:C,'Base Mercado'!A:A) -> 7 | J15: 3.79 | K15: 3.69 | L15: =IF(AND(K15<>"",K15<J15),K15,J15) -> 3.69
A16: 2 | B16: =_xlfn.XLOOKUP(A16,'Produtos & Marcas'!A:A,'Produtos & Marcas'!B:B) -> Açúcar | União | 1 | Kg | C16: =_xlfn.XLOOKUP(B16,'Produtos & Marcas'!B:B,'Produtos & Marcas'!C:C) -> Açúcar | D16: =_xlfn.XLOOKUP(B16,'Produtos & Marcas'!B:B,'Produtos & Marcas'!D:D) -> Kg | E16: =_xlfn.XLOOKUP(B16,'Produtos & Marcas'!B:B,'Produtos & Marcas'!E:E) -> 1 | F16: =J16/E16 -> 4.99 | G16: =_xlfn.XLOOKUP(B16,'Produtos & Marcas'!B:B,'Produtos & Marcas'!F:F) -> União | H16: União - Jardim Bonança | I16: =_xlfn.XLOOKUP(H16,'Base Mercado'!C:C,'Base Mercado'!A:A) -> 1 | J16: 4.99 | K16: 4.83 | L16: =IF(AND(K16<>"",K16<J16),K16,J16) -> 4.83
A17: 2 | B17: =_xlfn.XLOOKUP(A17,'Produtos & Marcas'!A:A,'Produtos & Marcas'!B:B) -> Açúcar | União | 1 | Kg | C17: =_xlfn.XLOOKUP(B17,'Produtos & Marcas'!B:B,'Produtos & Marcas'!C:C) -> Açúcar | D17: =_xlfn.XLOOKUP(B17,'Produtos & Marcas'!B:B,'Produtos & Marcas'!D:D) -> Kg | E17: =_xlfn.XLOOKUP(B17,'Produtos & Marcas'!B:B,'Produtos & Marcas'!E:E) -> 1 | F17: =J17/E17 -> 4.99 | G17: =_xlfn.XLOOKUP(B17,'Produtos & Marcas'!B:B,'Produtos & Marcas'!F:F) -> União | H17: Mendonça - Parque dos Estados | I17: =_xlfn.XLOOKUP(H17,'Base Mercado'!C:C,'Base Mercado'!A:A) -> 2 | J17: 4.99 | L17: =IF(AND(K17<>"",K17<J17),K17,J17) -> 4.99
A18: 2 | B18: =_xlfn.XLOOKUP(A18,'Produtos & Marcas'!A:A,'Produtos & Marcas'!B:B) -> Açúcar | União | 1 | Kg | C18: =_xlfn.XLOOKUP(B18,'Produtos & Marcas'!B:B,'Produtos & Marcas'!C:C) -> Açúcar | D18: =_xlfn.XLOOKUP(B18,'Produtos & Marcas'!B:B,'Produtos & Marcas'!D:D) -> Kg | E18: =_xlfn.XLOOKUP(B18,'Produtos & Marcas'!B:B,'Produtos & Marcas'!E:E) -> 1 | F18: =J18/E18 -> 4.99 | G18: =_xlfn.XLOOKUP(B18,'Produtos & Marcas'!B:B,'Produtos & Marcas'!F:F) -> União | H18: União - Centro | I18: =_xlfn.XLOOKUP(H18,'Base Mercado'!C:C,'Base Mercado'!A:A) -> 3 | J18: 4.99 | L18: =IF(AND(K18<>"",K18<J18),K18,J18) -> 4.99
A19: 2 | B19: =_xlfn.XLOOKUP(A19,'Produtos & Marcas'!A:A,'Produtos & Marcas'!B:B) -> Açúcar | União | 1 | Kg | C19: =_xlfn.XLOOKUP(B19,'Produtos & Marcas'!B:B,'Produtos & Marcas'!C:C) -> Açúcar | D19: =_xlfn.XLOOKUP(B19,'Produtos & Marcas'!B:B,'Produtos & Marcas'!D:D) -> Kg | E19: =_xlfn.XLOOKUP(B19,'Produtos & Marcas'!B:B,'Produtos & Marcas'!E:E) -> 1 | F19: =J19/E19 -> 6.99 | G19: =_xlfn.XLOOKUP(B19,'Produtos & Marcas'!B:B,'Produtos & Marcas'!F:F) -> União | H19: Mendonça - Centro | I19: =_xlfn.XLOOKUP(H19,'Base Mercado'!C:C,'Base Mercado'!A:A) -> 4 | J19: 6.99 | L19: =IF(AND(K19<>"",K19<J19),K19,J19) -> 6.99
A20: 2 | B20: =_xlfn.XLOOKUP(A20,'Produtos & Marcas'!A:A,'Produtos & Marcas'!B:B) -> Açúcar | União | 1 | Kg | C20: =_xlfn.XLOOKUP(B20,'Produtos & Marcas'!B:B,'Produtos & Marcas'!C:C) -> Açúcar | D20: =_xlfn.XLOOKUP(B20,'Produtos & Marcas'!B:B,'Produtos & Marcas'!D:D) -> Kg | E20: =_xlfn.XLOOKUP(B20,'Produtos & Marcas'!B:B,'Produtos & Marcas'!E:E) -> 1 | F20: =J20/E20 -> 3.99 | G20: =_xlfn.XLOOKUP(B20,'Produtos & Marcas'!B:B,'Produtos & Marcas'!F:F) -> União | H20: Comercial Esperança - Penha | I20: =_xlfn.XLOOKUP(H20,'Base Mercado'!C:C,'Base Mercado'!A:A) -> 5 | J20: 3.99 | K20: 3.86 | L20: =IF(AND(K20<>"",K20<J20),K20,J20) -> 3.86
A21: 2 | B21: =_xlfn.XLOOKUP(A21,'Produtos & Marcas'!A:A,'Produtos & Marcas'!B:B) -> Açúcar | União | 1 | Kg | C21: =_xlfn.XLOOKUP(B21,'Produtos & Marcas'!B:B,'Produtos & Marcas'!C:C) -> Açúcar | D21: =_xlfn.XLOOKUP(B21,'Produtos & Marcas'!B:B,'Produtos & Marcas'!D:D) -> Kg | E21: =_xlfn.XLOOKUP(B21,'Produtos & Marcas'!B:B,'Produtos & Marcas'!E:E) -> 1 | F21: =J21/E21 -> 3.99 | G21: =_xlfn.XLOOKUP(B21,'Produtos & Marcas'!B:B,'Produtos & Marcas'!F:F) -> União | H21: Spani Atacadista - Lago | I21: =_xlfn.XLOOKUP(H21,'Base Mercado'!C:C,'Base Mercado'!A:A) -> 6 | J21: 3.99 | K21: 3.89 | L21: =IF(AND(K21<>"",K21<J21),K21,J21) -> 3.89
A22: 2 | B22: =_xlfn.XLOOKUP(A22,'Produtos & Marcas'!A:A,'Produtos & Marcas'!B:B) -> Açúcar | União | 1 | Kg | C22: =_xlfn.XLOOKUP(B22,'Produtos & Marcas'!B:B,'Produtos & Marcas'!C:C) -> Açúcar | D22: =_xlfn.XLOOKUP(B22,'Produtos & Marcas'!B:B,'Produtos & Marcas'!D:D) -> Kg | E22: =_xlfn.XLOOKUP(B22,'Produtos & Marcas'!B:B,'Produtos & Marcas'!E:E) -> 1 | F22: =J22/E22 -> 5.99 | G22: =_xlfn.XLOOKUP(B22,'Produtos & Marcas'!B:B,'Produtos & Marcas'!F:F) -> União | H22: Spani Atacadista - Lavapés | I22: =_xlfn.XLOOKUP(H22,'Base Mercado'!C:C,'Base Mercado'!A:A) -> 7 | J22: 5.99 | K22: 5.89 | L22: =IF(AND(K22<>"",K22<J22),K22,J22) -> 5.89
A23: 4 | B23: =_xlfn.XLOOKUP(A23,'Produtos & Marcas'!A:A,'Produtos & Marcas'!B:B) -> Arroz | Namorado | 1 | Kg | C23: =_xlfn.XLOOKUP(B23,'Produtos & Marcas'!B:B,'Produtos & Marcas'!C:C) -> Arroz | D23: =_xlfn.XLOOKUP(B23,'Produtos & Marcas'!B:B,'Produtos & Marcas'!D:D) -> Kg | E23: =_xlfn.XLOOKUP(B23,'Produtos & Marcas'!B:B,'Produtos & Marcas'!E:E) -> 1 | F23: =J23/E23 -> 6.98 | G23: =_xlfn.XLOOKUP(B23,'Produtos & Marcas'!B:B,'Produtos & Marcas'!F:F) -> Namorado | H23: União - Jardim Bonança | I23: =_xlfn.XLOOKUP(H23,'Base Mercado'!C:C,'Base Mercado'!A:A) -> 1 | J23: 6.98 | K23: 6.83 | L23: =IF(AND(K23<>"",K23<J23),K23,J23) -> 6.83
A24: 4 | B24: =_xlfn.XLOOKUP(A24,'Produtos & Marcas'!A:A,'Produtos & Marcas'!B:B) -> Arroz | Namorado | 1 | Kg | C24: =_xlfn.XLOOKUP(B24,'Produtos & Marcas'!B:B,'Produtos & Marcas'!C:C) -> Arroz | D24: =_xlfn.XLOOKUP(B24,'Produtos & Marcas'!B:B,'Produtos & Marcas'!D:D) -> Kg | E24: =_xlfn.XLOOKUP(B24,'Produtos & Marcas'!B:B,'Produtos & Marcas'!E:E) -> 1 | F24: =J24/E24 -> 7.98 | G24: =_xlfn.XLOOKUP(B24,'Produtos & Marcas'!B:B,'Produtos & Marcas'!F:F) -> Namorado | H24: Mendonça - Parque dos Estados | I24: =_xlfn.XLOOKUP(H24,'Base Mercado'!C:C,'Base Mercado'!A:A) -> 2 | J24: 7.98 | K24: 7.83 | L24: =IF(AND(K24<>"",K24<J24),K24,J24) -> 7.83
A25: 4 | B25: =_xlfn.XLOOKUP(A25,'Produtos & Marcas'!A:A,'Produtos & Marcas'!B:B) -> Arroz | Namorado | 1 | Kg | C25: =_xlfn.XLOOKUP(B25,'Produtos & Marcas'!B:B,'Produtos & Marcas'!C:C) -> Arroz | D25: =_xlfn.XLOOKUP(B25,'Produtos & Marcas'!B:B,'Produtos & Marcas'!D:D) -> Kg | E25: =_xlfn.XLOOKUP(B25,'Produtos & Marcas'!B:B,'Produtos & Marcas'!E:E) -> 1 | F25: =J25/E25 -> 5.98 | G25: =_xlfn.XLOOKUP(B25,'Produtos & Marcas'!B:B,'Produtos & Marcas'!F:F) -> Namorado | H25: União - Centro | I25: =_xlfn.XLOOKUP(H25,'Base Mercado'!C:C,'Base Mercado'!A:A) -> 3 | J25: 5.98 | K25: 5.83 | L25: =IF(AND(K25<>"",K25<J25),K25,J25) -> 5.83
A26: 4 | B26: =_xlfn.XLOOKUP(A26,'Produtos & Marcas'!A:A,'Produtos & Marcas'!B:B) -> Arroz | Namorado | 1 | Kg | C26: =_xlfn.XLOOKUP(B26,'Produtos & Marcas'!B:B,'Produtos & Marcas'!C:C) -> Arroz | D26: =_xlfn.XLOOKUP(B26,'Produtos & Marcas'!B:B,'Produtos & Marcas'!D:D) -> Kg | E26: =_xlfn.XLOOKUP(B26,'Produtos & Marcas'!B:B,'Produtos & Marcas'!E:E) -> 1 | F26: =J26/E26 -> 5.98 | G26: =_xlfn.XLOOKUP(B26,'Produtos & Marcas'!B:B,'Produtos & Marcas'!F:F) -> Namorado | H26: Mendonça - Centro | I26: =_xlfn.XLOOKUP(H26,'Base Mercado'!C:C,'Base Mercado'!A:A) -> 4 | J26: 5.98 | K26: 5.83 | L26: =IF(AND(K26<>"",K26<J26),K26,J26) -> 5.83
A27: 4 | B27: =_xlfn.XLOOKUP(A27,'Produtos & Marcas'!A:A,'Produtos & Marcas'!B:B) -> Arroz | Namorado | 1 | Kg | C27: =_xlfn.XLOOKUP(B27,'Produtos & Marcas'!B:B,'Produtos & Marcas'!C:C) -> Arroz | D27: =_xlfn.XLOOKUP(B27,'Produtos & Marcas'!B:B,'Produtos & Marcas'!D:D) -> Kg | E27: =_xlfn.XLOOKUP(B27,'Produtos & Marcas'!B:B,'Produtos & Marcas'!E:E) -> 1 | F27: =J27/E27 -> 6.98 | G27: =_xlfn.XLOOKUP(B27,'Produtos & Marcas'!B:B,'Produtos & Marcas'!F:F) -> Namorado | H27: Comercial Esperança - Penha | I27: =_xlfn.XLOOKUP(H27,'Base Mercado'!C:C,'Base Mercado'!A:A) -> 5 | J27: 6.98 | L27: =IF(AND(K27<>"",K27<J27),K27,J27) -> 6.98
A28: 4 | B28: =_xlfn.XLOOKUP(A28,'Produtos & Marcas'!A:A,'Produtos & Marcas'!B:B) -> Arroz | Namorado | 1 | Kg | C28: =_xlfn.XLOOKUP(B28,'Produtos & Marcas'!B:B,'Produtos & Marcas'!C:C) -> Arroz | D28: =_xlfn.XLOOKUP(B28,'Produtos & Marcas'!B:B,'Produtos & Marcas'!D:D) -> Kg | E28: =_xlfn.XLOOKUP(B28,'Produtos & Marcas'!B:B,'Produtos & Marcas'!E:E) -> 1 | F28: =J28/E28 -> 8.98 | G28: =_xlfn.XLOOKUP(B28,'Produtos & Marcas'!B:B,'Produtos & Marcas'!F:F) -> Namorado | H28: Spani Atacadista - Lago | I28: =_xlfn.XLOOKUP(H28,'Base Mercado'!C:C,'Base Mercado'!A:A) -> 6 | J28: 8.98 | L28: =IF(AND(K28<>"",K28<J28),K28,J28) -> 8.98
A29: 4 | B29: =_xlfn.XLOOKUP(A29,'Produtos & Marcas'!A:A,'Produtos & Marcas'!B:B) -> Arroz | Namorado | 1 | Kg | C29: =_xlfn.XLOOKUP(B29,'Produtos & Marcas'!B:B,'Produtos & Marcas'!C:C) -> Arroz | D29: =_xlfn.XLOOKUP(B29,'Produtos & Marcas'!B:B,'Produtos & Marcas'!D:D) -> Kg | E29: =_xlfn.XLOOKUP(B29,'Produtos & Marcas'!B:B,'Produtos & Marcas'!E:E) -> 1 | F29: =J29/E29 -> 6.98 | G29: =_xlfn.XLOOKUP(B29,'Produtos & Marcas'!B:B,'Produtos & Marcas'!F:F) -> Namorado | H29: Spani Atacadista - Lavapés | I29: =_xlfn.XLOOKUP(H29,'Base Mercado'!C:C,'Base Mercado'!A:A) -> 7 | J29: 6.98 | L29: =IF(AND(K29<>"",K29<J29),K29,J29) -> 6.98
A30: 6 | B30: =_xlfn.XLOOKUP(A30,'Produtos & Marcas'!A:A,'Produtos & Marcas'!B:B) -> Arroz | Prato Fino | 1 | Kg | C30: =_xlfn.XLOOKUP(B30,'Produtos & Marcas'!B:B,'Produtos & Marcas'!C:C) -> Arroz | D30: =_xlfn.XLOOKUP(B30,'Produtos & Marcas'!B:B,'Produtos & Marcas'!D:D) -> Kg | E30: =_xlfn.XLOOKUP(B30,'Produtos & Marcas'!B:B,'Produtos & Marcas'!E:E) -> 1 | F30: =J30/E30 -> 5.99 | G30: =_xlfn.XLOOKUP(B30,'Produtos & Marcas'!B:B,'Produtos & Marcas'!F:F) -> Prato Fino | H30: União - Jardim Bonança | I30: =_xlfn.XLOOKUP(H30,'Base Mercado'!C:C,'Base Mercado'!A:A) -> 1 | J30: 5.99 | L30: =IF(AND(K30<>"",K30<J30),K30,J30) -> 5.99
A31: 6 | B31: =_xlfn.XLOOKUP(A31,'Produtos & Marcas'!A:A,'Produtos & Marcas'!B:B) -> Arroz | Prato Fino | 1 | Kg | C31: =_xlfn.XLOOKUP(B31,'Produtos & Marcas'!B:B,'Produtos & Marcas'!C:C) -> Arroz | D31: =_xlfn.XLOOKUP(B31,'Produtos & Marcas'!B:B,'Produtos & Marcas'!D:D) -> Kg | E31: =_xlfn.XLOOKUP(B31,'Produtos & Marcas'!B:B,'Produtos & Marcas'!E:E) -> 1 | F31: =J31/E31 -> 5.99 | G31: =_xlfn.XLOOKUP(B31,'Produtos & Marcas'!B:B,'Produtos & Marcas'!F:F) -> Prato Fino | H31: Mendonça - Parque dos Estados | I31: =_xlfn.XLOOKUP(H31,'Base Mercado'!C:C,'Base Mercado'!A:A) -> 2 | J31: 5.99 | L31: =IF(AND(K31<>"",K31<J31),K31,J31) -> 5.99
A32: 6 | B32: =_xlfn.XLOOKUP(A32,'Produtos & Marcas'!A:A,'Produtos & Marcas'!B:B) -> Arroz | Prato Fino | 1 | Kg | C32: =_xlfn.XLOOKUP(B32,'Produtos & Marcas'!B:B,'Produtos & Marcas'!C:C) -> Arroz | D32: =_xlfn.XLOOKUP(B32,'Produtos & Marcas'!B:B,'Produtos & Marcas'!D:D) -> Kg | E32: =_xlfn.XLOOKUP(B32,'Produtos & Marcas'!B:B,'Produtos & Marcas'!E:E) -> 1 | F32: =J32/E32 -> 5.99 | G32: =_xlfn.XLOOKUP(B32,'Produtos & Marcas'!B:B,'Produtos & Marcas'!F:F) -> Prato Fino | H32: União - Centro | I32: =_xlfn.XLOOKUP(H32,'Base Mercado'!C:C,'Base Mercado'!A:A) -> 3 | J32: 5.99 | L32: =IF(AND(K32<>"",K32<J32),K32,J32) -> 5.99
A33: 6 | B33: =_xlfn.XLOOKUP(A33,'Produtos & Marcas'!A:A,'Produtos & Marcas'!B:B) -> Arroz | Prato Fino | 1 | Kg | C33: =_xlfn.XLOOKUP(B33,'Produtos & Marcas'!B:B,'Produtos & Marcas'!C:C) -> Arroz | D33: =_xlfn.XLOOKUP(B33,'Produtos & Marcas'!B:B,'Produtos & Marcas'!D:D) -> Kg | E33: =_xlfn.XLOOKUP(B33,'Produtos & Marcas'!B:B,'Produtos & Marcas'!E:E) -> 1 | F33: =J33/E33 -> 6.99 | G33: =_xlfn.XLOOKUP(B33,'Produtos & Marcas'!B:B,'Produtos & Marcas'!F:F) -> Prato Fino | H33: Mendonça - Centro | I33: =_xlfn.XLOOKUP(H33,'Base Mercado'!C:C,'Base Mercado'!A:A) -> 4 | J33: 6.99 | L33: =IF(AND(K33<>"",K33<J33),K33,J33) -> 6.99
A34: 6 | B34: =_xlfn.XLOOKUP(A34,'Produtos & Marcas'!A:A,'Produtos & Marcas'!B:B) -> Arroz | Prato Fino | 1 | Kg | C34: =_xlfn.XLOOKUP(B34,'Produtos & Marcas'!B:B,'Produtos & Marcas'!C:C) -> Arroz | D34: =_xlfn.XLOOKUP(B34,'Produtos & Marcas'!B:B,'Produtos & Marcas'!D:D) -> Kg | E34: =_xlfn.XLOOKUP(B34,'Produtos & Marcas'!B:B,'Produtos & Marcas'!E:E) -> 1 | F34: =J34/E34 -> 4.99 | G34: =_xlfn.XLOOKUP(B34,'Produtos & Marcas'!B:B,'Produtos & Marcas'!F:F) -> Prato Fino | H34: Comercial Esperança - Penha | I34: =_xlfn.XLOOKUP(H34,'Base Mercado'!C:C,'Base Mercado'!A:A) -> 5 | J34: 4.99 | L34: =IF(AND(K34<>"",K34<J34),K34,J34) -> 4.99
A35: 6 | B35: =_xlfn.XLOOKUP(A35,'Produtos & Marcas'!A:A,'Produtos & Marcas'!B:B) -> Arroz | Prato Fino | 1 | Kg | C35: =_xlfn.XLOOKUP(B35,'Produtos & Marcas'!B:B,'Produtos & Marcas'!C:C) -> Arroz | D35: =_xlfn.XLOOKUP(B35,'Produtos & Marcas'!B:B,'Produtos & Marcas'!D:D) -> Kg | E35: =_xlfn.XLOOKUP(B35,'Produtos & Marcas'!B:B,'Produtos & Marcas'!E:E) -> 1 | F35: =J35/E35 -> 4.99 | G35: =_xlfn.XLOOKUP(B35,'Produtos & Marcas'!B:B,'Produtos & Marcas'!F:F) -> Prato Fino | H35: Spani Atacadista - Lago | I35: =_xlfn.XLOOKUP(H35,'Base Mercado'!C:C,'Base Mercado'!A:A) -> 6 | J35: 4.99 | L35: =IF(AND(K35<>"",K35<J35),K35,J35) -> 4.99
A36: 6 | B36: =_xlfn.XLOOKUP(A36,'Produtos & Marcas'!A:A,'Produtos & Marcas'!B:B) -> Arroz | Prato Fino | 1 | Kg | C36: =_xlfn.XLOOKUP(B36,'Produtos & Marcas'!B:B,'Produtos & Marcas'!C:C) -> Arroz | D36: =_xlfn.XLOOKUP(B36,'Produtos & Marcas'!B:B,'Produtos & Marcas'!D:D) -> Kg | E36: =_xlfn.XLOOKUP(B36,'Produtos & Marcas'!B:B,'Produtos & Marcas'!E:E) -> 1 | F36: =J36/E36 -> 5.99 | G36: =_xlfn.XLOOKUP(B36,'Produtos & Marcas'!B:B,'Produtos & Marcas'!F:F) -> Prato Fino | H36: Spani Atacadista - Lavapés | I36: =_xlfn.XLOOKUP(H36,'Base Mercado'!C:C,'Base Mercado'!A:A) -> 7 | J36: 5.99 | L36: =IF(AND(K36<>"",K36<J36),K36,J36) -> 5.99
A37: 5 | B37: =_xlfn.XLOOKUP(A37,'Produtos & Marcas'!A:A,'Produtos & Marcas'!B:B) -> Arroz | Tio João | 1 | Kg | C37: =_xlfn.XLOOKUP(B37,'Produtos & Marcas'!B:B,'Produtos & Marcas'!C:C) -> Arroz | D37: =_xlfn.XLOOKUP(B37,'Produtos & Marcas'!B:B,'Produtos & Marcas'!D:D) -> Kg | E37: =_xlfn.XLOOKUP(B37,'Produtos & Marcas'!B:B,'Produtos & Marcas'!E:E) -> 1 | F37: =J37/E37 -> 6.35 | G37: =_xlfn.XLOOKUP(B37,'Produtos & Marcas'!B:B,'Produtos & Marcas'!F:F) -> Tio João | H37: União - Jardim Bonança | I37: =_xlfn.XLOOKUP(H37,'Base Mercado'!C:C,'Base Mercado'!A:A) -> 1 | J37: 6.35 | L37: =IF(AND(K37<>"",K37<J37),K37,J37) -> 6.35
A38: 5 | B38: =_xlfn.XLOOKUP(A38,'Produtos & Marcas'!A:A,'Produtos & Marcas'!B:B) -> Arroz | Tio João | 1 | Kg | C38: =_xlfn.XLOOKUP(B38,'Produtos & Marcas'!B:B,'Produtos & Marcas'!C:C) -> Arroz | D38: =_xlfn.XLOOKUP(B38,'Produtos & Marcas'!B:B,'Produtos & Marcas'!D:D) -> Kg | E38: =_xlfn.XLOOKUP(B38,'Produtos & Marcas'!B:B,'Produtos & Marcas'!E:E) -> 1 | F38: =J38/E38 -> 7.35 | G38: =_xlfn.XLOOKUP(B38,'Produtos & Marcas'!B:B,'Produtos & Marcas'!F:F) -> Tio João | H38: Mendonça - Parque dos Estados | I38: =_xlfn.XLOOKUP(H38,'Base Mercado'!C:C,'Base Mercado'!A:A) -> 2 | J38: 7.35 | L38: =IF(AND(K38<>"",K38<J38),K38,J38) -> 7.35
... A54: 7 | B54: =_xlfn.XLOOKUP(A54,'Produtos & Marcas'!A:A,'Produtos & Marcas'!B:B) -> Banana | Banana Nanica | 1 | Kg | C54: =_xlfn.XLOOKUP(B54,'Produtos & Marcas'!B:B,'Produtos & Marcas'!C:C) -> Banana | D54: =_xlfn.XLOOKUP(B54,'Produtos & Marcas'!B:B,'Produtos & Marcas'!D:D) -> Kg | E54: =_xlfn.XLOOKUP(B54,'Produtos & Marcas'!B:B,'Produtos & Marcas'!E:E) -> 1 | F54: =J54/E54 -> 5.99 | G54: =_xlfn.XLOOKUP(B54,'Produtos & Marcas'!B:B,'Produtos & Marcas'!F:F) -> Banana Nanica | H54: Mendonça - Centro | I54: =_xlfn.XLOOKUP(H54,'Base Mercado'!C:C,'Base Mercado'!A:A) -> 4 | J54: 5.99 | L54: =IF(AND(K54<>"",K54<J54),K54,J54) -> 5.99
A55: 7 | B55: =_xlfn.XLOOKUP(A55,'Produtos & Marcas'!A:A,'Produtos & Marcas'!B:B) -> Banana | Banana Nanica | 1 | Kg | C55: =_xlfn.XLOOKUP(B55,'Produtos & Marcas'!B:B,'Produtos & Marcas'!C:C) -> Banana | D55: =_xlfn.XLOOKUP(B55,'Produtos & Marcas'!B:B,'Produtos & Marcas'!D:D) -> Kg | E55: =_xlfn.XLOOKUP(B55,'Produtos & Marcas'!B:B,'Produtos & Marcas'!E:E) -> 1 | F55: =J55/E55 -> 5.99 | G55: =_xlfn.XLOOKUP(B55,'Produtos & Marcas'!B:B,'Produtos & Marcas'!F:F) -> Banana Nanica | H55: Comercial Esperança - Penha | I55: =_xlfn.XLOOKUP(H55,'Base Mercado'!C:C,'Base Mercado'!A:A) -> 5 | J55: 5.99 | K55: 5.84 | L55: =IF(AND(K55<>"",K55<J55),K55,J55) -> 5.84
...

Sheet Compras
A1: ID Lista | B1: Item | Marca | C1: ID Produto | D1: Quantidade | E1: Ponto de Partida | F1: ID Ponto de Partida
A2: 89 | B2: Arroz | Namorado | 1 | Kg | C2: =_xlfn.XLOOKUP(B2,'Produtos & Marcas'!B:B,'Produtos & Marcas'!A:A) -> 4 | D2: 5 | E2: R. da Tecnologia - Res. Hipica Jaguari, Bragança Paulista - SP, 12926-677 | F2: =_xlfn.XLOOKUP(E2,'Pontos de Partida'!B:B,'Pontos de Partida'!A:A) -> 4
A3: 89 | B3: Banana | Banana Prata | 1 | Kg | C3: =_xlfn.XLOOKUP(B3,'Produtos & Marcas'!B:B,'Produtos & Marcas'!A:A) -> 8 | D3: 1 | E3: R. da Tecnologia - Res. Hipica Jaguari, Bragança Paulista - SP, 12926-677 | F3: =_xlfn.XLOOKUP(E3,'Pontos de Partida'!B:B,'Pontos de Partida'!A:A) -> 4
A4: 89 | B4: Café em pó | 3 Corações | 1 | Kg | C4: =_xlfn.XLOOKUP(B4,'Produtos & Marcas'!B:B,'Produtos & Marcas'!A:A) -> 14 | D4: 1 | E4: R. da Tecnologia - Res. Hipica Jaguari, Bragança Paulista - SP, 12926-677 | F4: =_xlfn.XLOOKUP(E4,'Pontos de Partida'!B:B,'Pontos de Partida'!A:A) -> 4
A5: 89 | B5: Farinha de Trigo | Dona Benta | 1 | Kg | C5: =_xlfn.XLOOKUP(B5,'Produtos & Marcas'!B:B,'Produtos & Marcas'!A:A) -> 19 | D5: 2 | E5: R. da Tecnologia - Res. Hipica Jaguari, Bragança Paulista - SP, 12926-677 | F5: =_xlfn.XLOOKUP(E5,'Pontos de Partida'!B:B,'Pontos de Partida'!A:A) -> 4
A6: 89 | B6: Feijão | Broto Legal | 1 | Kg | C6: =_xlfn.XLOOKUP(B6,'Produtos & Marcas'!B:B,'Produtos & Marcas'!A:A) -> 24 | D6: 3 | E6: R. da Tecnologia - Res. Hipica Jaguari, Bragança Paulista - SP, 12926-677 | F6: =_xlfn.XLOOKUP(E6,'Pontos de Partida'!B:B,'Pontos de Partida'!A:A) -> 4
A7: 89 | B7: Margarina | Doriana | 0,5 | Kg | C7: =_xlfn.XLOOKUP(B7,'Produtos & Marcas'!B:B,'Produtos & Marcas'!A:A) -> 28 | D7: 2 | E7: R. da Tecnologia - Res. Hipica Jaguari, Bragança Paulista - SP, 12926-677 | F7: =_xlfn.XLOOKUP(E7,'Pontos de Partida'!B:B,'Pontos de Partida'!A:A) -> 4
A8: 89 | B8: Pães | Pão Francês | 1 | Kg | C8: =_xlfn.XLOOKUP(B8,'Produtos & Marcas'!B:B,'Produtos & Marcas'!A:A) -> 34 | D8: 0.2 | E8: R. da Tecnologia - Res. Hipica Jaguari, Bragança Paulista - SP, 12926-677 | F8: =_xlfn.XLOOKUP(E8,'Pontos de Partida'!B:B,'Pontos de Partida'!A:A) -> 4
A9: 89 | B9: Tomate | Tomate comum | 1 | Kg | C9: =_xlfn.XLOOKUP(B9,'Produtos & Marcas'!B:B,'Produtos & Marcas'!A:A) -> 37 | D9: 1 | E9: R. da Tecnologia - Res. Hipica Jaguari, Bragança Paulista - SP, 12926-677 | F9: =_xlfn.XLOOKUP(E9,'Pontos de Partida'!B:B,'Pontos de Partida'!A:A) -> 4
A10: 89 | B10: Batata | Batata Asterix selecionada | 1 | Kg | C10: =_xlfn.XLOOKUP(B10,'Produtos & Marcas'!B:B,'Produtos & Marcas'!A:A) -> 11 | D10: 4 | E10: R. da Tecnologia - Res. Hipica Jaguari, Bragança Paulista - SP, 12926-677 | F10: =_xlfn.XLOOKUP(E10,'Pontos de Partida'!B:B,'Pontos de Partida'!A:A) -> 4
A11: 89 | B11: Leite | Nestlé Ninho | 1 | Unidade | C11: =_xlfn.XLOOKUP(B11,'Produtos & Marcas'!B:B,'Produtos & Marcas'!A:A) -> 26 | D11: 2 | E11: R. da Tecnologia - Res. Hipica Jaguari, Bragança Paulista - SP, 12926-677 | F11: =_xlfn.XLOOKUP(E11,'Pontos de Partida'!B:B,'Pontos de Partida'!A:A) -> 4
A12: 89 | B12: Óleo | Óleo Soya | 1 | Unidade | C12: =_xlfn.XLOOKUP(B12,'Produtos & Marcas'!B:B,'Produtos & Marcas'!A:A) -> 32 | D12: 3 | E12: R. da Tecnologia - Res. Hipica Jaguari, Bragança Paulista - SP, 12926-677 | F12: =_xlfn.XLOOKUP(E12,'Pontos de Partida'!B:B,'Pontos de Partida'!A:A) -> 4
A13: =A2+1 -> 90 | B13: Arroz | Namorado | 1 | Kg | C13: =_xlfn.XLOOKUP(B13,'Produtos & Marcas'!B:B,'Produtos & Marcas'!A:A) -> 4 | D13: 5 | E13: Av. Dr. Manoel José Vilaça - Jardim America, Bragança Paulista - SP | F13: =_xlfn.XLOOKUP(E13,'Pontos de Partida'!B:B,'Pontos de Partida'!A:A) -> 1
A14: =A3+1 -> 90 | B14: Banana | Banana Prata | 1 | Kg | C14: =_xlfn.XLOOKUP(B14,'Produtos & Marcas'!B:B,'Produtos & Marcas'!A:A) -> 8 | D14: 1 | E14: Av. Dr. Manoel José Vilaça - Jardim America, Bragança Paulista - SP | F14: =_xlfn.XLOOKUP(E14,'Pontos de Partida'!B:B,'Pontos de Partida'!A:A) -> 1
A15: =A4+1 -> 90 | B15: Café em pó | 3 Corações | 1 | Kg | C15: =_xlfn.XLOOKUP(B15,'Produtos & Marcas'!B:B,'Produtos & Marcas'!A:A) -> 14 | D15: 1 | E15: Av. Dr. Manoel José Vilaça - Jardim America, Bragança Paulista - SP | F15: =_xlfn.XLOOKUP(E15,'Pontos de Partida'!B:B,'Pontos de Partida'!A:A) -> 1
A16: =A5+1 -> 90 | B16: Farinha de Trigo | Dona Benta | 1 | Kg | C16: =_xlfn.XLOOKUP(B16,'Produtos & Marcas'!B:B,'Produtos & Marcas'!A:A) -> 19 | D16: 2 | E16: Av. Dr. Manoel José Vilaça - Jardim America, Bragança Paulista - SP | F16: =_xlfn.XLOOKUP(E16,'Pontos de Partida'!B:B,'Pontos de Partida'!A:A) -> 1
A17: =A6+1 -> 90 | B17: Feijão | Broto Legal | 1 | Kg | C17: =_xlfn.XLOOKUP(B17,'Produtos & Marcas'!B:B,'Produtos & Marcas'!A:A) -> 24 | D17: 3 | E17: Av. Dr. Manoel José Vilaça - Jardim America, Bragança Paulista - SP | F17: =_xlfn.XLOOKUP(E17,'Pontos de Partida'!B:B,'Pontos de Partida'!A:A) -> 1
A18: =A7+1 -> 90 | B18: Margarina | Doriana | 0,5 | Kg | C18: =_xlfn.XLOOKUP(B18,'Produtos & Marcas'!B:B,'Produtos & Marcas'!A:A) -> 28 | D18: 2 | E18: Av. Dr. Manoel José Vilaça - Jardim America, Bragança Paulista - SP | F18: =_xlfn.XLOOKUP(E18,'Pontos de Partida'!B:B,'Pontos de Partida'!A:A) -> 1
A19: =A8+1 -> 90 | B19: Pães | Pão Francês | 1 | Kg | C19: =_xlfn.XLOOKUP(B19,'Produtos & Marcas'!B:B,'Produtos & Marcas'!A:A) -> 34 | D19: 0.2 | E19: Av. Dr. Manoel José Vilaça - Jardim America, Bragança Paulista - SP | F19: =_xlfn.XLOOKUP(E19,'Pontos de Partida'!B:B,'Pontos de Partida'!A:A) -> 1
A20: =A9+1 -> 90 | B20: Tomate | Tomate comum | 1 | Kg | C20: =_xlfn.XLOOKUP(B20,'Produtos & Marcas'!B:B,'Produtos & Marcas'!A:A) -> 37 | D20: 1 | E20: Av. Dr. Manoel José Vilaça - Jardim America, Bragança Paulista - SP | F20: =_xlfn.XLOOKUP(E20,'Pontos de Partida'!B:B,'Pontos de Partida'!A:A) -> 1
A21: =A10+1 -> 90 | B21: Batata | Batata Asterix selecionada | 1 | Kg | C21: =_xlfn.XLOOKUP(B21,'Produtos & Marcas'!B:B,'Produtos & Marcas'!A:A) -> 11 | D21: 4 | E21: Av. Dr. Manoel José Vilaça - Jardim America, Bragança Paulista - SP | F21: =_xlfn.XLOOKUP(E21,'Pontos de Partida'!B:B,'Pontos de Partida'!A:A) -> 1
A22: =A11+1 -> 90 | B22: Leite | Nestlé Ninho | 1 | Unidade | C22: =_xlfn.XLOOKUP(B22,'Produtos & Marcas'!B:B,'Produtos & Marcas'!A:A) -> 26 | D22: 2 | E22: Av. Dr. Manoel José Vilaça - Jardim America, Bragança Paulista - SP | F22: =_xlfn.XLOOKUP(E22,'Pontos de Partida'!B:B,'Pontos de Partida'!A:A) -> 1
A23: =A12+1 -> 90 | B23: Óleo | Óleo Soya | 1 | Unidade | C23: =_xlfn.XLOOKUP(B23,'Produtos & Marcas'!B:B,'Produtos & Marcas'!A:A) -> 32 | D23: 3 | E23: Av. Dr. Manoel José Vilaça - Jardim America, Bragança Paulista - SP | F23: =_xlfn.XLOOKUP(E23,'Pontos de Partida'!B:B,'Pontos de Partida'!A:A) -> 1
A24: =A13+1 -> 91 | B24: Arroz | Namorado | 1 | Kg | C24: =_xlfn.XLOOKUP(B24,'Produtos & Marcas'!B:B,'Produtos & Marcas'!A:A) -> 4 | D24: 5 | E24: R. Adele Pagetti - Cidade Planejada I, Bragança Paulista - SP, 12922-060 | F24: =_xlfn.XLOOKUP(E24,'Pontos de Partida'!B:B,'Pontos de Partida'!A:A) -> 2
... A177: =A166+1 -> 104 | B177: Margarina | Qualy | 0,5 | Kg | C177: =_xlfn.XLOOKUP(B177,'Produtos & Marcas'!B:B,'Produtos & Marcas'!A:A) -> 29 | D177: 1 | E177: R. Cel. Luís Leme - Jardim Santa Rita de Cassia, Bragança Paulista - SP, 12914-010 | F177: =_xlfn.XLOOKUP(E177,'Pontos de Partida'!B:B,'Pontos de Partida'!A:A) -> 8
A178: 1 | B178: Arroz | Prato Fino | 1 | Kg | C178: =_xlfn.XLOOKUP(B178,'Produtos & Marcas'!B:B,'Produtos & Marcas'!A:A) -> 6 | D178: 3 | E178: Av. Dr. Manoel José Vilaça - Jardim America, Bragança Paulista - SP | F178: =_xlfn.XLOOKUP(E178,'Pontos de Partida'!B:B,'Pontos de Partida'!A:A) -> 1
A179: 1 | B179: Açúcar | Guarani | 1 | Kg | C179: =_xlfn.XLOOKUP(B179,'Produtos & Marcas'!B:B,'Produtos & Marcas'!A:A) -> 3 | D179: 2 | E179: Av. Dr. Manoel José Vilaça - Jardim America, Bragança Paulista - SP | F179: =_xlfn.XLOOKUP(E179,'Pontos de Partida'!B:B,'Pontos de Partida'!A:A) -> 1
A180: 1 | B180: Banana | Banana maçã | 1 | Kg | C180: =_xlfn.XLOOKUP(B180,'Produtos & Marcas'!B:B,'Produtos & Marcas'!A:A) -> 9 | D180: 0.4 | E180: Av. Dr. Manoel José Vilaça - Jardim America, Bragança Paulista - SP | F180: =_xlfn.XLOOKUP(E180,'Pontos de Partida'!B:B,'Pontos de Partida'!A:A) -> 1
A181: 1 | B181: Batata | Batata doce | 1 | Kg | C181: =_xlfn.XLOOKUP(B181,'Produtos & Marcas'!B:B,'Produtos & Marcas'!A:A) -> 12 | D181: 0.8 | E181: Av. Dr. Manoel José Vilaça - Jardim America, Bragança Paulista - SP | F181: =_xlfn.XLOOKUP(E181,'Pontos de Partida'!B:B,'Pontos de Partida'!A:A) -> 1
A182: 1 | B182: Café em pó | Caboclo | 1 | Kg | C182: =_xlfn.XLOOKUP(B182,'Produtos & Marcas'!B:B,'Produtos & Marcas'!A:A) -> 13 | D182: 1 | E182: Av. Dr. Manoel José Vilaça - Jardim America, Bragança Paulista - SP | F182: =_xlfn.XLOOKUP(E182,'Pontos de Partida'!B:B,'Pontos de Partida'!A:A) -> 1
A183: 1 | B183: Carne | Acém | 1 | Kg | C183: =_xlfn.XLOOKUP(B183,'Produtos & Marcas'!B:B,'Produtos & Marcas'!A:A) -> 16 | D183: 1.5 | E183: Av. Dr. Manoel José Vilaça - Jardim America, Bragança Paulista - SP | F183: =_xlfn.XLOOKUP(E183,'Pontos de Partida'!B:B,'Pontos de Partida'!A:A) -> 1
A184: 1 | B184: Farinha de Trigo | Dona Benta | 1 | Kg | C184: =_xlfn.XLOOKUP(B184,'Produtos & Marcas'!B:B,'Produtos & Marcas'!A:A) -> 19 | D184: 1 | E184: Av. Dr. Manoel José Vilaça - Jardim America, Bragança Paulista - SP | F184: =_xlfn.XLOOKUP(E184,'Pontos de Partida'!B:B,'Pontos de Partida'!A:A) -> 1
A185: 1 | B185: Feijão | Camil | 1 | Kg | C185: =_xlfn.XLOOKUP(B185,'Produtos & Marcas'!B:B,'Produtos & Marcas'!A:A) -> 23 | D185: 3 | E185: Av. Dr. Manoel José Vilaça - Jardim America, Bragança Paulista - SP | F185: =_xlfn.XLOOKUP(E185,'Pontos de Partida'!B:B,'Pontos de Partida'!A:A) -> 1
A186: 1 | B186: Leite | Tirol | 1 | Unidade | C186: =_xlfn.XLOOKUP(B186,'Produtos & Marcas'!B:B,'Produtos & Marcas'!A:A) -> 27 | D186: 2 | E186: Av. Dr. Manoel José Vilaça - Jardim America, Bragança Paulista - SP | F186: =_xlfn.XLOOKUP(E186,'Pontos de Partida'!B:B,'Pontos de Partida'!A:A) -> 1
A187: 1 | B187: Margarina | Doriana | 0,5 | Kg | C187: =_xlfn.XLOOKUP(B187,'Produtos & Marcas'!B:B,'Produtos & Marcas'!A:A) -> 28 | D187: 1 | E187: Av. Dr. Manoel José Vilaça - Jardim America, Bragança Paulista - SP | F187: =_xlfn.XLOOKUP(E187,'Pontos de Partida'!B:B,'Pontos de Partida'!A:A) -> 1
A188: 1 | B188: Pães | Pão Francês | 1 | Kg | C188: =_xlfn.XLOOKUP(B188,'Produtos & Marcas'!B:B,'Produtos & Marcas'!A:A) -> 34 | D188: 0.2 | E188: Av. Dr. Manoel José Vilaça - Jardim America, Bragança Paulista - SP | F188: =_xlfn.XLOOKUP(E188,'Pontos de Partida'!B:B,'Pontos de Partida'!A:A) -> 1
A189: 1 | B189: Tomate | Tomate comum | 1 | Kg | C189: =_xlfn.XLOOKUP(B189,'Produtos & Marcas'!B:B,'Produtos & Marcas'!A:A) -> 37 | D189: 0.5 | E189: Av. Dr. Manoel José Vilaça - Jardim America, Bragança Paulista - SP | F189: =_xlfn.XLOOKUP(E189,'Pontos de Partida'!B:B,'Pontos de Partida'!A:A) -> 1
... A269: 11 | B269: Açúcar | União | 1 | Kg | C269: =_xlfn.XLOOKUP(B269,'Produtos & Marcas'!B:B,'Produtos & Marcas'!A:A) -> 2 | D269: 2 | E269: Av. Dr. Manoel José Vilaça - Jardim America, Bragança Paulista - SP | F269: =_xlfn.XLOOKUP(E269,'Pontos de Partida'!B:B,'Pontos de Partida'!A:A) -> 1
A270: =A178+11 -> 12 | B270: Arroz | Prato Fino | 1 | Kg | C270: =_xlfn.XLOOKUP(B270,'Produtos & Marcas'!B:B,'Produtos & Marcas'!A:A) -> 6 | D270: 3 | E270: R. Adele Pagetti - Cidade Planejada I, Bragança Paulista - SP, 12922-060 | F270: =_xlfn.XLOOKUP(E270,'Pontos de Partida'!B:B,'Pontos de Partida'!A:A) -> 2
A271: =A179+11 -> 12 | B271: Açúcar | Guarani | 1 | Kg | C271: =_xlfn.XLOOKUP(B271,'Produtos & Marcas'!B:B,'Produtos & Marcas'!A:A) -> 3 | D271: 2 | E271: R. Adele Pagetti - Cidade Planejada I, Bragança Paulista - SP, 12922-060 | F271: =_xlfn.XLOOKUP(E271,'Pontos de Partida'!B:B,'Pontos de Partida'!A:A) -> 2
...

Sheet Base Produtos OLD
A1: Produto | B1: Marca | C1: ID Mercado | D1: Mercado | E1: Preço | F1: Peso (g) | G1: Descrição Extra Produto
A2: Pão de Forma | B2: Seven Boys | C2: 1 | D2: =VLOOKUP(C2,'Base Mercado'!A:C,2,0) -> União | E2: 6.99 | F2: 400
A3: Pão de Forma | B3: Seven Boys | C3: 2 | D3: =VLOOKUP(C3,'Base Mercado'!A:C,2,0) -> Mendonça | E3: 7.49 | F3: 400
A4: Pão de Forma | B4: Seven Boys | C4: 3 | D4: =VLOOKUP(C4,'Base Mercado'!A:C,2,0) -> União | E4: 7.15 | F4: 400
A5: Pão de Forma | B5: Seven Boys | C5: 4 | D5: =VLOOKUP(C5,'Base Mercado'!A:C,2,0) -> Mendonça | E5: 5.49 | F5: 400
A6: Pão de Forma | B6: Seven Boys | C6: 5 | D6: =VLOOKUP(C6,'Base Mercado'!A:C,2,0) -> Comercial Esperança | E6: 8.99 | F6: 400
A7: Café | B7: Pilão | C7: 1 | D7: =VLOOKUP(C7,'Base Mercado'!A:C,2,0) -> União | E7: 33.5 | F7: 500
A8: Café | B8: Pilão | C8: 2 | D8: =VLOOKUP(C8,'Base Mercado'!A:C,2,0) -> Mendonça | E8: 35.75 | F8: 500
A9: Café | B9: Pilão | C9: 3 | D9: =VLOOKUP(C9,'Base Mercado'!A:C,2,0) -> União | E9: 34.6 | F9: 500
A10: Café | B10: Pilão | C10: 4 | D10: =VLOOKUP(C10,'Base Mercado'!A:C,2,0) -> Mendonça | E10: 31.9 | F10: 500
A11: Café | B11: Pilão | C11: 5 | D11: =VLOOKUP(C11,'Base Mercado'!A:C,2,0) -> Comercial Esperança | E11: 29.75 | F11: 500
A12: Leite | B12: Shefa | C12: 1 | D12: =VLOOKUP(C12,'Base Mercado'!A:C,2,0) -> União | E12: 3.89 | F12: 1000
A13: Leite | B13: Shefa | C13: 2 | D13: =VLOOKUP(C13,'Base Mercado'!A:C,2,0) -> Mendonça | E13: 4.25 | F13: 1000
... A26: Arroz | B26: Bonachão | C26: 5 | D26: =VLOOKUP(C26,'Base Mercado'!A:C,2,0) -> Comercial Esperança | E26: 22.69 | F26: 1000

Sheet Lista Produtos Cliente OLD
A1: Produto | B1: Marca | C1: Endereço Cliente | D1: Peso Preço (1 menor a 5 maior) | E1: Peso Distancia (1 a 5)
A2: Pão de Forma | B2: Seven Boys | C2: Rua da Tecnologia - 536 - CEP 12926677 | D2: 2 | E2: 3
A3: Café | B3: Pilão | C3: Rua da Tecnologia - 536 - CEP 12926677 | D3: 5 | E3: 2
A4: Leite | B4: Shefa | C4: Rua da Tecnologia - 536 - CEP 12926677 | D4: 5 | E4: 1
A5: Batata | B5: Monalisa | C5: Rua da Tecnologia - 536 - CEP 12926677 | D5: 1 | E5: 5
A6: Arroz | B6: Bonachão | C6: Rua da Tecnologia - 536 - CEP 12926677 | D6: 3 | E6: 4
